Workbook

Sheet BALANCAN
A1: INFORME BALANCAN 2025/2026 | M1: =TODAY() -> 46205
A4: SOCIOS | C4: - | D4: APORTACIÓN | E4: 1000000 | F4: RECUPERADO | G4: =H8*M8+H9*M9 -> 289151.78 | H4: PENDIENTE | I4: =E4-G4 -> 710848.22 | K4: RECUPERADO APORTACIÓN% | L4: =G4/E4 -> 0.28915178
K5: COBRADO PROYECTOS% | L5: =M8 -> 1
A7: No. | B7: AÑO | C7: NOMBRE DEL PROYECTO | D7: ESTATUS | F7: POR COBRAR | G7: INVERSIÓN | H7: UTILIDAD TOTAL | I7: UTILIDAD JEFE | J7: % | K7: ÁREA ENCARGADA | L7: AVANCE FÍSICO | M7: AVANCE FINANCIERO
A8: 1 | B8: 2025 | C8: 2000 Despensas | D8: Terminado | F8: =756000-75600 -> 680400 | G8: 556000 | H8: =118400 -> 118400 | I8: =H8 -> 118400 | J8: =H8/F8 -> 0.17401529 | K8: Recursos Materiales | L8: 1 | M8: 1
A9: 2 | B9: 2026 | C9: Obra | D9: Obra en proceso de ejecución Calendarizado. Quedo ingresada la primera estimación por la cantidad de $211,916.00 Factura 1183 | F9: 2642190.5 | G9: 1725000 | H9: 569172.6 | I9: =H9 -> 569172.6 | J9: 0.42 | K9: Obras | L9: 0.4 | M9: 0.3
E10: TOTALES | F10: =SUM(F8:F9) -> 3322590.5 | G10: =SUM(G8:G9) -> 2281000 | H10: =SUM(H8:H9) -> 687572.6 | I10: =SUM(I8:I9) -> 687572.6
E12: PORCENTAJE DE UTILIDAD DE LOS PROYECTOS | H12: =H10/F10 -> 0.20693871

Sheet CENTLA
A1: INFORME CENTLA 2025/2026 | M1: =TODAY() -> 46205
A4: SOCIOS | C4: 1 | D4: APORTACIÓN | E4: 3000000 | F4: RECUPERADO | G4: =H8*M8+H9*M9+H10*M10 -> 2942133.1 | H4: UTILIDAD | I4: =H11-E4 -> -3000000 | K4: RECUPERADO APORTACIÓN% | L4: =G4/E4 -> 0.98071103
K5: COBRADO PROYECTOS% | L5: =AVERAGE(M8:M9) -> 1
A7: No. | B7: AÑO | C7: NOMBRE DEL PROYECTO | D7: ESTATUS | F7: POR COBRAR | G7: INVERSIÓN | H7: UTILIDAD TOTAL | I7: UTILIDAD JEFE | J7: % | K7: ÁREA ENCARGADA | L7: AVANCE FÍSICO | M7: AVANCE FINANCIERO
A8: 1 | B8: 2025 | C8: Drenaje y pavimentación de Calle Melchor Ocampo (Administración) | D8: Terminado | F8: =8328557.14/1.16 -> 7179790.6 | G8: 4705273.8 | H8: 840893.12 | I8: =H8/2 -> 420446.56 | J8: =H8/CENTLA!G8 -> 0.1787129 | K8: Obras | L8: 1 | M8: 1
A9: 2 | B9: 2025 | C9: Pavimentación en la Calle C. Colorado (Administración) | D9: Terminado | F9: =9303329.73/1.16 -> 8020111.8 | G9: 6283798.7 | H9: 2012846.6 | I9: =H9/2 -> 1006423.3 | J9: =H9/F9 -> 0.25097488 | K9: Obras | L9: 1 | M9: 1
A10: 3 | B10: 2026 | C10: Drenaje y Agua Potable | D10: Se terminó la ejecución de los los trabajos de Agua Potable. Estimacion 1 de Drenaje en proceso de pago; Estimacion 1 finiquito de Agua Potable en tramite | F10: 1303172.7 | G10: 770487.09 | H10: 294644.53 | I10: =H10/2 -> 147322.27 | J10: =H10/F10 -> 0.22609784 | K10: Obras | L10: 0.98 | M10: 0.3
A11: 3 | B11: 2026 | C11: Alumbrado | D11: Obra asignada, con inicio 10/07/26, monto aproximado $503,630.50 hasta su asignación. Solicitaron dar inicio adelantado. | F11: 0 | G11: 0 | H11: 0 | I11: =H11/2 -> 0 | J11: =H11/F11 -> #DIV/0! | K11: Obras/Licitaciones | L11: 0 | M11: 0
E13: PORCENTAJE DE UTILIDAD DE LOS PROYECTOS | H13: =H11/F11 -> #DIV/0!

Sheet COMALCALCO
A1: INFORME COMALCALCO 2025/2026 | M1: =TODAY() -> 46205
A4: SOCIOS | C4: - | D4: APORTACIÓN | E4: =23000+30000 -> 53000 | F4: RECUPERADO | G4: =H8*M8 -> 169907.38 | H4: UTILIDAD | I4: =I9-E4 -> 116907.38 | K4: RECUPERADO APORTACIÓN% | L4: 1
K5: COBRADO PROYECTOS% | L5: =M8 -> 1
A7: No. | B7: AÑO | C7: NOMBRE DEL PROYECTO | D7: ESTATUS | F7: POR COBRAR | G7: INVERSIÓN | H7: UTILIDAD TOTAL | I7: UTILIDAD JEFE | J7: % | K7: ÁREA ENCARGADA | L7: AVANCE FÍSICO | M7: AVANCE FINANCIERO
A8: 1 | B8: 2025 | C8: Luminaras Tec de comalcalco | D8: PAGADO (Trabajos terminados y entregados) | F8: =546677.16/1.16 -> 471273.41 | G8: 288942.28 | H8: 169907.38 | I8: =H8 -> 169907.38 | J8: =H8/F8 -> 0.36052825 | K8: Obras | L8: 1 | M8: 1
E9: TOTALES | F9: =SUM(F8:F8) -> 471273.41 | G9: =SUM(G8:G8) -> 288942.28 | H9: =SUM(H8:H8) -> 169907.38 | I9: =SUM(I8:I8) -> 169907.38
E11: PORCENTAJE DE UTILIDAD DE LOS PROYECTOS | H11: =H9/F9 -> 0.36052825

Sheet DURANGO
A1: INFORME DURANGO 2025/2026 | M1: =TODAY() -> 46205
A4: SOCIOS | C4: - | D4: APORTACIÓN | E4: 5000000 | F4: RECUPERADO | G4: =H9 -> 0 | H4: PENDIENTE | I4: =E4-G4 -> 5000000 | K4: RECUPERADO APORTACIÓN% | L4: =G4/E4 -> 0
K5: COBRADO PROYECTOS% | L5: =M8 -> 0
A7: No. | B7: AÑO | C7: NOMBRE DEL PROYECTO | D7: ESTATUS | F7: POR COBRAR | G7: INVERSIÓN | H7: UTILIDAD TOTAL | I7: UTILIDAD JEFE | J7: % | K7: ÁREA ENCARGADA | L7: AVANCE FÍSICO | M7: AVANCE FINANCIERO
A8: 1 | B8: 2026 | C8: Iluminación Mpio. Rodeo | D8: Mañana me cito Don Pedro para ver el tema de Durango | K8: Obras
E9: TOTALES | F9: =SUM(F8) -> 0 | G9: =SUM(G8:G8) -> 0 | H9: =SUM(H8:H8) -> 0 | I9: =SUM(I8:I8) -> 0
E11: PORCENTAJE DE UTILIDAD DE LOS PROYECTOS

Sheet ENSENADA
A1: INFORME ENSENADA 2025/2026 | M1: =TODAY() -> 46205
A4: SOCIOS | C4: - | D4: APORTACIÓN | F4: RECUPERADO | G4: =H10 -> 0 | H4: PENDIENTE | I4: =E4-G4 -> 0 | K4: RECUPERADO APORTACIÓN%
K5: COBRADO PROYECTOS% | L5: =M8 -> 0
A7: No. | B7: AÑO | C7: NOMBRE DEL PROYECTO | D7: ESTATUS | F7: POR COBRAR | G7: INVERSIÓN | H7: UTILIDAD TOTAL | I7: UTILIDAD JEFE | J7: % | K7: ÁREA ENCARGADA | L7: AVANCE FÍSICO | M7: AVANCE FINANCIERO
A8: 1 | B8: 2026 | C8: Iluminación | D8: Este proyecto se hará hasta el siguiente año. Ya que no cuentan con el recurso. Se hará un proyecto para que con eso puedan pedir el recurso. | K8: Obras
A9: 2 | B9: 2026 | C9: Obra Pavimentación | D9: El proyecto ya se entregó a Obras Públicas, el día Lunes 29 nos lo hacen llegar y teniendo el presupuesto autorizado se realizará la Corrida Financiera con un monto aproximado del proyecto aun en proceso de autorización de $7,352,817.00 El próximo miércoles 01 de julio tendremos el documento del convenio para ser firmado por las partes. | K9: Obras
E10: TOTALES | F10: =SUM(F8) -> 0 | G10: =SUM(G8:G8) -> 0 | H10: =SUM(H8:H8) -> 0 | I10: =SUM(I8:I8) -> 0
E12: PORCENTAJE DE UTILIDAD DE LOS PROYECTOS

Sheet JALPA
A1: INFORME JALPA DE MENDEZ 2025/2026 | M1: =TODAY() -> 46205
A4: SOCIOS | C4: - | D4: APORTACIÓN | E4: 1500000 | F4: RECUPERADO | G4: =H8+H9*(M9)+H10*M10+H11*M11+H12*M12+H13*M13+H14*M14+H15*M15 -> 1973619 | H4: UTILIDAD | I4: =I16-E4 -> 2154056.7 | K4: RECUPERADO APORTACIÓN% | L4: =G4/E4 -> 1.315746
K5: COBRADO PROYECTOS% | L5: =AVERAGE(M8:M15) -> 0.9125
A7: No. | B7: AÑO | C7: NOMBRE DEL PROYECTO | D7: ESTATUS | F7: POR COBRAR | G7: INVERSIÓN | H7: UTILIDAD TOTAL | I7: UTILIDAD JEFE | J7: % | K7: ÁREA ENCARGADA | L7: AVANCE FÍSICO | M7: AVANCE FINANCIERO
A8: 1 | B8: 2025 | C8: Luminarias de OXXO a Vialidad principal | D8: Terminado | F8: =1413525.64/1.16 -> 1218556.6 | G8: 915713 | H8: =273542.04*M8 -> 273542.04 | I8: =H8 -> 273542.04 | J8: =H8/F8 -> 0.22448038 | K8: Obras | L8: 1 | M8: 1
A9: 2 | B9: 2025 | C9: Ampliación de la Red de energía eléctrica Chacalapa | D9: Terminado | F9: =1204783.92/1.16 -> 1038606.8 | G9: 874765.97 | H9: 166598.86 | I9: =H9 -> 166598.86 | J9: =H9/F9 -> 0.16040609 | K9: Obras | L9: 1 | M9: 1 | O9: CONTRATO CON IVA | P9: 0.3 | Q9: ACUMULADO | R9: DIFERENCIA
A10: 3 | B10: 2025 | C10: I0062.- REHABILITACIÓN DE CAMINO EN TRAMOS ENTRADA LOS CANDELERO Y ENTRADA AL PANTEÓN DE LA RA. SANTUARIO 1RA SECCIÓN | D10: Terminado | F10: 514735.32 | G10: 382364.03 | H10: 117597.94 | I10: =H10 -> 117597.94 | J10: =I10/F10 -> 0.22846293 | K10: Obras | L10: 1 | M10: 1 | O10: 597092.98 | P10: 175127.89 | Q10: =417952.02+P10 -> 593079.91 | R10: =+O10-Q10 -> 4013.07
A11: 4 | B11: 2025 | C11: I0072.- REHABILITACIÓN DE CAMINO EN VARIOS TRAMOS DE LA RA CHACALAPA SEGUNDA SECCIÓN COL OSORIO | D11: Terminada y pagada | F11: =900024.77/1.16 -> 775883.42 | G11: 591537.19 | H11: 181970.97 | I11: =H11 -> 181970.97 | J11: =I11/F11 -> 0.23453391 | K11: Obras | L11: 1 | M11: 1 | O11: 900024.77 | P11: 270007.43
A12: 5 | B12: 2025 | C12: I0078.- REHABILITACIÓN DE CAMINO TRAMO LA MANGA DEL EJIDO EL PÚLPITO | D12: Terminada y pagada | F12: =587009.59/1.16 -> 506042.75 | G12: 375093.53 | H12: 118114.64 | I12: =H12 -> 118114.64 | J12: =I12/F12 -> 0.23340842 | K12: Obras | L12: 1 | M12: 1 | O12: =+F12*1.16 -> 587009.59 | P12: 176127.89
A13: 6 | B13: 2025 | C13: I0086.- REHABILITACIÓN DE CAMINO EN EL EJIDO IQUINUAPA | D13: Terminada y pagada | F13: =885738.04/1.16 -> 763567.28 | G13: 582809.84 | H13: 177939.34 | I13: =H13 -> 177939.34 | J13: =I13/F13 -> 0.23303689 | K13: Obras | L13: 1 | M13: 1 | O13: =763567.28*1.16 -> 885738.04 | P13: 265721.4 | Q13: =+P13+258943.55 -> 524664.95 | R13: =+O13-Q13 -> 361073.09
A14: 7 | B14: 2025 | C14: I0079.- REHABILITACIÓN DE CAMINO EN VARIOS TRAMOS DE LA RA HUAPACAL 2DA SECCIÓN | D14: Terminada y pagada | F14: =1048267.91/1.16 -> 903679.23 | G14: 688421.12 | H14: 217667.66 | I14: =H14 -> 217667.66 | J14: =I14/F14 -> 0.24086828 | K14: Obras | L14: 1 | M14: 1 | O14: 1048267.5 | P14: 314480.37 | Q14: =+P14+183892.99 -> 498373.36 | R14: =+O14-Q14 -> 549894.15
A15: 8 | B15: 2026 | C15: REHABILITACIÓN CARRETERA EL CARMEN | D15: Obra en proceso, se está trabajando en la primera estimación con un monto aproximado de $2.3 mdp. El cierre de la estimación sera el 30 de Junio y se pagará en un periodo aproximado de 10 días. | F15: =10133799.15/1.16 -> 8736033.8 | G15: 6470266.7 | H15: 2400625.3 | I15: =H15 -> 2400625.3 | J15: 0.24 | K15: Obras | L15: 0.4 | M15: 0.3
E16: TOTALES | F16: =SUM(F8:F15) -> 14457105 | G16: =SUM(G8:G15) -> 10880971 | H16: =SUM(H8:H15) -> 3654056.7 | I16: =SUM(I8:I15) -> 3654056.7
E18: PORCENTAJE DE UTILIDAD DE LOS PROYECTOS | H18: =H16/F16 -> 0.25275162

Sheet JALAPA
A1: INFORME JALAPA 2025/2026 | M1: =TODAY() -> 46205
A4: SOCIOS | C4: - | D4: APORTACIÓN | E4: 900000 | F4: RECUPERADO | G4: =(I8*M8+I9*M9+I10*M10+I11*M11+I12*M12+I13*M13) -> 413263.04 | H4: PENDIENTE | I4: =E4-G4 -> 486736.96 | K4: RECUPERADO APORTACIÓN% | L4: =G4/E4 -> 0.45918116
K5: COBRADO PROYECTOS% | L5: =AVERAGE(M8:M13) -> 0.5
A7: No. | B7: AÑO | C7: NOMBRE DEL PROYECTO | D7: ESTATUS | F7: POR COBRAR | G7: INVERSIÓN | H7: UTILIDAD TOTAL | I7: UTILIDAD JEFE | J7: % | K7: ÁREA ENCARGADA | L7: AVANCE FÍSICO | M7: AVANCE FINANCIERO
A8: 1 | B8: 2025 | C8: Colocación de 156 Luminarias | D8: Terminado | F8: =1082808.99/1.16 -> 933456.03 | G8: 459050 | H8: 331697.6 | I8: =H8 -> 331697.6 | J8: =H8/F8 -> 0.35534357 | K8: Obras | L8: 1 | M8: 1
A9: 2 | B9: 2025 | C9: Material de Cómputo y de Jardinería | D9: Terminado | F9: =199604.47/1.16 -> 172072.82 | G9: 136130.34 | H9: 32927.21 | I9: =H9 -> 32927.21 | J9: =H9/F9 -> 0.19135625 | K9: Recursos Materiales | L9: 1 | M9: 1
A10: 3 | B10: 2025 | C10: Trajes para abejas | D10: En regularización | F10: =29232/1.16 -> 25200 | G10: 12145.2 | H10: 8769.6 | I10: 8769.6 | J10: =H10/F10 -> 0.348 | K10: Recursos Materiales | L10: 1 | M10: 0
A11: 4 | B11: 2025 | C11: Luminarias | D11: En regularizacióny se va a pagar en el 2026 porque ya no hay presupuesto | F11: 113680 | G11: =31320+26448 -> 57768 | H11: =11542.4+29128 -> 40670.4 | I11: =H11 -> 40670.4 | J11: =I11/F11 -> 0.35776214 | K11: Recursos Materiales | L11: 1 | M11: 0
A12: 5 | B12: 2026 | C12: Arrendamiento de 4 unidades pickup | D12: Estamos en espera de que nos asignen el presupuesto | F12: 418800 | G12: =G13/2*3 -> 306842.65 | H12: =H13/2*3 -> 72957.345 | I12: =I13/2*3 -> 72957.345 | J12: =H12/F12 -> 0.17420569 | K12: Recursos Materiales | L12: 1 | M12: 0
A13: 6 | B13: 2025 | C13: Arrendamiento de 4 unidades pickup | D13: Estas unidades son las de Teapa, ahorita salió el contrato solo por nov y diciembre. | F13: 279200 | G13: 204561.77 | H13: 48638.23 | I13: =H13 -> 48638.23 | J13: =I13/F13 -> 0.17420569 | K13: Recursos Materiales | L13: 1 | M13: 1
E14: TOTALES | F14: =SUM(F8:F13) -> 1942408.8 | G14: =SUM(G8:G13) -> 1176498 | H14: =SUM(H8:H13) -> 535660.39 | I14: =SUM(I8:I13) -> 535660.39
E16: PORCENTAJE DE UTILIDAD DE LOS PROYECTOS | H16: =H14/F14 -> 0.27577118

Sheet JONUTA
A1: INFORME JONUTA 2025/2026 | M1: =TODAY() -> 46205
A4: SOCIOS | C4: 1 | D4: APORTACIÓN | E4: 1575000 | F4: RECUPERADO | G4: =H8*M8+H9*M9+H10*M10+H11*M11 -> 1256360.2 | H4: PENDIENTE | I4: =E4-G4 -> 318639.77 | K4: RECUPERADO APORTACIÓN% | L4: =G4/E4 -> 0.79768904
K5: COBRADO PROYECTOS% | L5: =AVERAGE(M8:M10) -> 0.66666667
A7: No. | B7: AÑO | C7: NOMBRE DEL PROYECTO | D7: ESTATUS | F7: POR COBRAR | G7: INVERSIÓN | H7: UTILIDAD TOTAL | I7: UTILIDAD JEFE | J7: % | K7: ÁREA ENCARGADA | L7: AVANCE FÍSICO | M7: AVANCE FINANCIERO
A8: 1 | B8: 2025 | C8: Jonuta motosierras | D8: Ya se tiene el recurso y ya se metió la factura, solo en espera de cobro | F8: =50225.41/1.16 -> 43297.767 | G8: 37204.01 | H8: 7496.61 | I8: =H8/2 -> 3748.305 | J8: =H8/F8 -> 0.1731408 | K8: Recursos Materiales | L8: 1 | M8: 0
A9: 2 | B9: 2025 | C9: Rehabilitación de Cubiertas de lámina en viviendas | D9: Pagado y Terminado | F9: =2443923.89/1.16 -> 2106830.9 | G9: 1458492.9 | H9: 655495.23 | I9: =H9/2 -> 327747.61 | J9: =H9/F9 -> 0.31112854 | K9: Obras | L9: 1 | M9: 1
A10: 3 | B10: 2025 | C10: Mejoramiento de la Deportiva (Parque del Amor) | D10: Pagado y Terminado | F10: =1309514.09/1.16 -> 1128891.5 | G10: 750000 | H10: 340304.2 | I10: =H10/2 -> 170152.1 | J10: =H10/F10 -> 0.30144989 | K10: Obras | L10: 1 | M10: 1
A11: 4 | B11: 2026 | C11: Pavimentación en Calle Violeta Ojeda | D11: Se concluyó con la obra de Pavimentación, martes 30/06/26, estamos en espera del pago correspondiente a la Estimación Finiquito por la cantidad de $716,401.60 | F11: =1648245.87/1.16 -> 1420901.6 | G11: =955744.93+82843.08 -> 1038588 | H11: 372229.72 | I11: =H11/2 -> 186114.86 | J11: =H11/F11 -> 0.26196727 | K11: Obras | L11: 1 | M11: 0.7
E12: TOTALES | F12: =SUM(F8:F11) -> 4699921.8 | G12: =SUM(G8:G11) -> 3284285 | H12: =SUM(H8:H11) -> 1375525.8 | I12: =SUM(I8:I11) -> 687762.88
E14: PORCENTAJE DE UTILIDAD DE LOS PROYECTOS | H14: =H12/F12 -> 0.29266993

Sheet MERIDA
A1: INFORME DE MÉRIDA 2025/2026 | M1: =TODAY() -> 46205
A4: SOCIOS | C4: 1 | D4: APORTACIÓN | E4: 2000000 | F4: RECUPERADO | G4: =H8*M8+H9*M9+H10*M10+H11*M11+H12*M12+H13*M13+H14*M14 -> 5032722.1 | H4: UTILIDAD | I4: =H15-E4 -> 4560703.6 | K4: RECUPERADO APORTACIÓN% | L4: =G4/E4 -> 2.5163611
K5: COBRADO PROYECTOS% | L5: =AVERAGE(M8:M11) -> 1
A7: No. | B7: AÑO | C7: NOMBRE DEL PROYECTO | D7: ESTATUS | F7: POR COBRAR | G7: INVERSIÓN | H7: UTILIDAD TOTAL | I7: UTILIDAD JEFE | J7: % | K7: ÁREA ENCARGADA | L7: AVANCE FÍSICO | M7: AVANCE FINANCIERO
A8: 1 | B8: 2025 | C8: Pavimentación | D8: Terminado y pagado | F8: =2619983.82/1.16 -> 2258606.7 | G8: 580000 | H8: 299950.43 | I8: =H8/2 -> 149975.21 | J8: =H8/F8 -> 0.1328033 | K8: Obras | L8: 1 | M8: 1
A9: 2 | B9: 2025 | C9: Pavimentación | D9: Terminado y pagado | F9: =8969013.43/1.16 -> 7731908.1 | G9: 3331600 | H9: 1409110.5 | I9: =H9/2 -> 704555.23 | J9: =H9/F9 -> 0.18224615 | K9: Obras | L9: 1 | M9: 1
A10: 3 | B10: 2025 | C10: Repavimentación de calle juan pablo 2do. (pavimento flexible) | D10: Terminado y pagado | F10: =3730600/1.16 -> 3216034.5 | G10: 1000000 | H10: =433381.02+150000 -> 583381.02 | I10: =H10/2 -> 291690.51 | J10: =H10/F10 -> 0.18139763 | K10: Obras | L10: 1 | M10: 1 | O10: Presupuesto Autorizado | P10: Estimación 1 | Q10: pendiente 2026
A11: 4 | B11: 2025 | C11: Repavimentación de calle contrato 168 | D11: Terminado y pagado | F11: =4099653.4/1.16 -> 3534184 | G11: 2675790.8 | H11: 997636.32 | I11: =H11/2 -> 498818.16 | J11: 0.22 | K11: Obras | L11: 1 | M11: 1 | O11: =+F11*1.16 -> 4099653.4 | P11: 3534184 | Q11: =+O11-P11 -> 565469.43
A12: 5 | B12: 2026 | C12: Repavimentación de calle contrato 267 | D12: Terminado y pagado (Reporte Entregado 11-06-2026) | F12: =3769722.18/1.16 -> 3249760.5 | G12: 2600894.4 | H12: 773656.86 | I12: =H12/2 -> 386828.43 | J12: 0.21 | K12: Obras | L12: 1 | M12: 1
A13: 6 | B13: 2026 | C13: Pavimento Asfáltico Contrato 6 | D13: Obra en ejecución, En proceso la Segunda estimación por la cantidad de 2.7 mdp, ingresa el lunes 29/06/26 | F13: =4699433.26/1.16 -> 4051235.6 | G13: =2990522.34+102700 -> 3093222.3 | H13: 1099482.4 | I13: =H13/2 -> 549741.19 | J13: 0.22 | K13: Obras | L13: 0.9 | M13: 0.5
A14: 7 | B14: 2026 | C14: Repavimentación Asfalto en Caliente Mérida 7 | D14: Obra en ejecución, En proceso la primera estimación, por ingresar el viernes 03/07/26 con un monto aproximado de $3.2mdp | F14: =5699710.99/1.16 -> 4913544 | G14: =3565000+98700 -> 3663700 | H14: 1397486.1 | I14: =H14/2 -> 698743.06 | J14: 0.25 | K14: Obras | L14: 0.8 | M14: 0.3
E15: TOTALES | F15: =SUM(F8:F14) -> 28955273 | G15: =SUM(G8:G14) -> 16945208 | H15: =SUM(H8:H14) -> 6560703.6 | I15: =SUM(I8:I14) -> 3280351.8
E17: PORCENTAJE DE UTILIDAD DE LOS PROYECTOS | H17: =H15/F15 -> 0.22658061

Sheet NACAJUCA
A1: INFORME NACAJUCA 2025/2026 | M1: =TODAY() -> 46205
A4: SOCIOS | C4: - | D4: APORTACIÓN | E4: - | F4: RECUPERADO | G4: - | H4: UTILIDAD | I4: =H9 -> 1095045 | K4: RECUPERADO APORTACIÓN% | L4: -
K5: COBRADO PROYECTOS% | L5: =M8 -> 1
A7: No. | B7: AÑO | C7: NOMBRE DEL PROYECTO | D7: ESTATUS | F7: POR COBRAR | G7: INVERSIÓN | H7: UTILIDAD TOTAL | I7: UTILIDAD JEFE | J7: % | K7: ÁREA ENCARGADA | L7: AVANCE FÍSICO | M7: AVANCE FINANCIERO
A8: 1 | B8: 2025 | C8: Nacajuca luminarias | D8: Terminado y pagado | F8: =6087912/1.16 -> 5248200 | G8: 3510725.3 | H8: 1095045 | I8: =H8 -> 1095045 | J8: =H8/F8 -> 0.20865154 | K8: Obras | L8: 1 | M8: 1
E9: TOTALES | F9: =SUM(F8:F8) -> 5248200 | G9: =SUM(G8:G8) -> 3510725.3 | H9: =SUM(H8:H8) -> 1095045 | I9: =SUM(I8:I8) -> 1095045
E11: PORCENTAJE DE UTILIDAD DE LOS PROYECTOS | H11: =H9/F9 -> 0.20865154

Sheet NAUCALPAN
A1: INFORME NAUCALPAN 2025/2026 | M1: =TODAY() -> 46205
A4: SOCIOS | C4: - | D4: APORTACIÓN | E4: 3000000 | F4: RECUPERADO | G4: =H8+M8+H9*M9+H10*M10+H11*M11+H12*M12 -> 10742197 | H4: UTILIDAD | I4: =H13-E4 -> 7742196 | K4: RECUPERADO APORTACIÓN% | L4: =G4/E4 -> 3.5807323
K5: COBRADO PROYECTOS% | L5: =AVERAGE(M8:M11) -> 1
A7: No. | B7: AÑO | C7: NOMBRE DEL PROYECTO | D7: ESTATUS | F7: POR COBRAR | G7: INVERSIÓN | H7: UTILIDAD TOTAL | I7: UTILIDAD JEFE | J7: % | K7: ÁREA ENCARGADA | L7: AVANCE FÍSICO | M7: AVANCE FINANCIERO
A8: 1 | B8: 2025 | C8: 5,000 despensas | D8: Terminado y pagado | F8: 1500000 | G8: 950000 | H8: 272000 | I8: =H8 -> 272000 | J8: =H8/F8 -> 0.18133333 | K8: Recursos Materiales | L8: 1 | M8: 1
A9: 2 | B9: 2025 | C9: 1,000 despensas | D9: Terminado y pagado | F9: 290000 | G9: 180000 | H9: 55700 | I9: =H9 -> 55700 | J9: =H9/F9 -> 0.19206897 | K9: Recursos Materiales | L9: 1 | M9: 1
A10: 3 | B10: 2025 | C10: 71,000 despensas | D10: Ya se pago el total de las despensas, solo falta entregar 20,000 despensas | F10: =(40115000)*0.9-428000-1500000 -> 34175500 | G10: =2707985.33+12716312.21+7212431.44 -> 22636729 | H10: =1193766.57+5673412.79+3547316.66 -> 10414496 | I10: =H10 -> 10414496 | J10: =H10/F10 -> 0.30473573 | K10: Recursos Materiales | L10: 0.7 | M10: 1
A11: 4 | B11: 2026 | C11: Obra de San Fernando | D11: Proyecto de pavimentación y Drenaje y Agua potable, ya fueron entregados a las áreas correspondientes, internamente estan realizando el proceso de licitación, esta semana nos dicen fecha de proceso. El día de hoy 26-06-26 solicitaron un cambio en el proyecto de drenaje y agua potable y la modificación de 6 conceptos. | K11: Obras/Licitación
A12: 5 | B12: 2026 | C12: Despensas | D12: Ya se tuvo cita con el nuevo director y estamos esperando que nos indiquen el presupuesto. Esta semana nos citaron para ver el tema | K12: Recursos Materiales
E13: TOTALES | F13: =SUM(F8:F12) -> 35965500 | G13: =SUM(G8:G12) -> 23766729 | H13: =SUM(H8:H12) -> 10742196 | I13: =SUM(I8:I12) -> 10742196
E15: PORCENTAJE DE UTILIDAD DE LOS PROYECTOS | H15: =H13/F13 -> 0.29868057
I19: =7345000+4708710 -> 12053710

Sheet PARAISO
A1: INFORME PARAISO 2025/2026 | M1: =TODAY() -> 46205
A4: SOCIOS | C4: - | D4: APORTACIÓN | E4: - | F4: COBRADO | G4: =H8*M8+H9*M9+H10*M10+H11*M11+H12*M12+H13*M13+H14*M14+H15*M15+H16*M16+H17*M17 -> 4425683.2 | H4: UTILIDAD | I4: =H18 -> 10468440 | K4: RECUPERADO APORTACIÓN% | L4: -
K5: COBRADO PROYECTOS% | L5: =AVERAGE(M8:M17) -> 0.26
A7: No. | B7: AÑO | C7: NOMBRE DEL PROYECTO | D7: ESTATUS | F7: POR COBRAR | G7: INVERSIÓN | H7: UTILIDAD TOTAL | I7: UTILIDAD JEFE | J7: % | K7: ÁREA ENCARGADA | L7: AVANCE FÍSICO | M7: AVANCE FINANCIERO
A8: 1 | B8: 2025 | C8: Vialidad A | D8: Terminado y pagado | F8: =3452505.5/1.16 -> 2976297.8 | G8: 2670115.8 | H8: 761555.64 | I8: =H8 -> 761555.64 | J8: =H8/F8 -> 0.25587346 | K8: Obras | L8: 1 | M8: 1
A9: =A8+1 -> 2 | B9: 2025 | C9: Polideportivo | D9: Ya se analizaron los precios, están en espera de que llegue el presupuesto para iniciar el proceso de licitación | F9: =1250283.9/1.16 -> 1077830.9 | G9: 714012.43 | H9: 282250.36 | I9: =H9 -> 282250.36 | J9: =H9/F9 -> 0.26186886 | K9: Obras | L9: 1 | M9: 0
A10: =A9+1 -> 3 | B10: 2025 | C10: Estadio de beisbol, Maximiliano Dorantes | D10: Ya se analizaron los precios, están en espera de que llegue el presupuesto para iniciar el proceso de licitación | F10: =215828.73/1.16 -> 186059.25 | G10: 168547.91 | H10: 47741.3 | I10: =H10 -> 47741.3 | J10: =H10/F10 -> 0.25659192 | K10: Obras | L10: 1 | M10: 0
A11: =A10+1 -> 4 | B11: 2025 | C11: Ruta 1 | D11: ya pagaron otra parte del proyecto por $469,178.65 | F11: =15552804.6/1.16 -> 13407590 | G11: 8616578.2 | H11: 4880038.3 | I11: =H11 -> 4880038.3 | J11: =H11/F11 -> 0.3639758 | K11: Obras | L11: 1 | M11: 0.6
A12: =A11+1 -> 5 | B12: 2025 | C12: La Feria Paraiso | D12: Ya se analizaron los precios, están en espera de que llegue el presupuesto para iniciar el proceso de licitación | F12: =2891456.91/1.16 -> 2492635.3 | G12: 1659470.4 | H12: 549004.4 | I12: =H12 -> 549004.4 | J12: =H12/F12 -> 0.22025059 | K12: Obras | L12: 1 | M12: 0
A13: =A12+1 -> 6 | B13: 2025 | C13: Villa Puerto Ceiba | D13: Se inició propyecto de Iluminación el día 4 de Nov y se concluyó el día lunes 10 de Nov 2025/2026 (El pago está programado para 2026) | F13: =2043047.82/1.16 -> 1761248.1 | G13: =F13*0.7 -> 1232873.7 | H13: =F13-G13 -> 528374.44 | I13: =H13 -> 528374.44 | J13: =H13/F13 -> 0.3 | K13: Obras | L13: 1 | M13: 0
A14: =A13+1 -> 7 | B14: 2025 | C14: Ejido Puerto Ceiba (Carrizal) | D14: Ya se analizaron los precios, están en espera de que llegue el presupuesto para iniciar el proceso de licitación | F14: =2271855.34/1.16 -> 1958496 | G14: 1515468.6 | H14: 622811.3 | I14: =H14 -> 622811.3 | J14: =H14/F14 -> 0.31800489 | K14: Obras | L14: 1 | M14: 0
A15: =A14+1 -> 8 | B15: 2025 | C15: =_xlfn.CONCAT(E34:E40) -> Ejido Jose Maria Morelos y Pavon (El Bellote)Ejido Chiltepec (Sección Banco)Ejido Chiltepec (Sección Tanque)Poblado Chiltepec (Puerto Chiltepec)Colonia Chiltepec (Sección Penjamo)Ejido Aquiles SerdanRancheria Aguiles Serdan | D15: Se terminaron los trabajos el dia 18/04/26 | F15: =SUM(F34:F40)/1.16 -> 6188400.2 | G15: =F15*0.7 -> 4331880.2 | H15: =F15-G15 -> 1856520.1 | I15: =H15 -> 1856520.1 | J15: =H15/F15 -> 0.3 | K15: Obras | L15: 1 | M15: 0
A16: =A15+1 -> 9 | B16: 2025 | C16: Nvo. Torno Largo, torno largo | D16: Pagado | F16: =(F24+F25+F26)/1.16 -> 2453681.8 | G16: =F16*0.7 -> 1717577.3 | H16: =F16-G16 -> 736104.55 | I16: =H16 -> 736104.55 | J16: =H16/F16 -> 0.3 | K16: Obras | L16: 1 | M16: 1
A17: =A16+1 -> 10 | B17: 2025 | C17: Tableros Eléctricos de la Feria | D17: Ya se analizaron los precios, están en espera de que llegue el presupuesto para iniciar el proceso de licitación | F17: =1108700.02/1.16 -> 955775.88 | G17: 619020.04 | H17: 204040.13 | I17: =H17 -> 204040.13 | J17: =H17/F17 -> 0.21348115 | K17: Obras | L17: 1 | M17: 0
E18: TOTALES | F18: =SUM(F8:F17) -> 33458016 | G18: =SUM(G8:G17) -> 23245545 | H18: =SUM(H8:H17) -> 10468440 | I18: =SUM(I8:I17) -> 10468440
E20: PORCENTAJE DE UTILIDAD DE LOS PROYECTOS | H20: =H18/F18 -> 0.31288289
C23: No. | D23: RUTA | E23: COMUNIDAD | F23: MONTO | G23: STATUS
C24: 16 | D24: Ruta 4 | E24: Nuevo Torno Largo * | F24: 1574368.1 | G24: Contratado | I24: 12 | J24: Ruta 4 | K24: Ejido Puerto Ceiba (Carrizal) | L24: 2271855.3 | M24: Pendiente de pago
C25: 17 | D25: Ruta 4 | E25: Torno Largo | F25: 594160.12 | G25: Contratado | I25: 13 | J25: Ruta 4 | K25: Feria | L25: 2891456.9 | M25: Pendiente de pago
C26: 18 | D26: Ruta 4 | E26: Colonia El Bellote (Miguel de la Madrid) | F26: 677742.64 | G26: Contratado | I26: 14 | J26: Ruta 4 | K26: Tableros | L26: 1108702.8 | M26: Pendiente de pago
I27: 15 | J27: Ruta 4 | K27: Villa Puerto Ceiba | L27: 2043047.8 | M27: Pendiente de pago
C34: 19 | D34: Ruta 4 | E34: Ejido Jose Maria Morelos y Pavon (El Bellote) | F34: 422242.46 | G34: Por cerrar volúmenes
C35: 20 | D35: Ruta 4 | E35: Ejido Chiltepec (Sección Banco) | F35: 723647.37 | G35: Por cerrar volúmenes
C36: 21 | D36: Ruta 4 | E36: Ejido Chiltepec (Sección Tanque) | F36: 321030.12 | G36: Por cerrar volúmenes
C37: 22 | D37: Ruta 4 | E37: Poblado Chiltepec (Puerto Chiltepec) | F37: 529677.69 | G37: Por cerrar volúmenes
C38: 23 | D38: Ruta 4 | E38: Colonia Chiltepec (Sección Penjamo) | F38: 3980224.5 | G38: Por cerrar volúmenes
C39: 24 | D39: Ruta 4 | E39: Ejido Aquiles Serdan | F39: 459149.99 | G39: Por cerrar volúmenes
C40: 25 | D40: Ruta 4 | E40: Rancheria Aguiles Serdan | F40: 742572.13 | G40: Por cerrar volúmenes

Sheet PICHU
A1: INFORME PICHUCALCO 2025/2026 | M1: =TODAY() -> 46205
A4: SOCIOS | C4: 1 | D4: APORTACIÓN | E4: 3000000 | F4: RECUPERADO | G4: =I8*M8+I9*M9+I10*M10+I11*M11+I12*M12+I13*M13+I14*M14+I15*M15+I16*M16+I17*M17+I18*M18+I19*M19+I20*M20+I21*M21+I22*M22+I23*M23+I24*M24+I25*M25+I26*M26 -> 2636541.9 | H4: UTILIDAD | I4: =I29-E4 -> 253295.63 | K4: RECUPERADO APORTACIÓN% | L4: =G4/E4 -> 0.87884731
K5: COBRADO PROYECTOS% | L5: =AVERAGE(M8:M26) -> 0.88859649
A7: No. | B7: AÑO | C7: NOMBRE DEL PROYECTO | D7: ESTATUS | F7: POR COBRAR | G7: INVERSIÓN | H7: UTILIDAD TOTAL | I7: UTILIDAD JEFE | J7: % | K7: ÁREA ENCARGADA | L7: AVANCE FÍSICO | M7: AVANCE FINANCIERO
A8: 1 | B8: 2025 | C8: Feria | D8: Pagaron $1,746,255.95 por los proyectos de desazolve, caminos rurales y de los pozos y $192,000. Se abonaron $300,000 de los pozos de agua | F8: 430390 | G8: 4147761.4 | H8: 779914 | I8: =H8/2+20000 -> 409957 | J8: =H8/F8 -> 1.8121099 | K8: Proyectos | L8: 1 | M8: 0.85
A9: =A8+1 -> 2 | B9: 2025 | C9: 2 Pipas de Agua en arrendamiento | D9: Se han hecho 15 pagos de 30 | F9: =2505600/1.16 -> 2160000 | G9: 1058225.9 | H9: 670782.05 | I9: =H9/2+40000 -> 375391.03 | J9: =H9/F9 -> 0.31054725 | K9: Proyectos | L9: 0.5 | M9: =15/30 -> 0.5
A10: =A9+1 -> 3 | B10: 2025 | C10: 5 Camionetas en arrendamiento | D10: Se han hecho 16 pagos de 30 | F10: =5220000/1.16 -> 4500000 | G10: 1965579.7 | H10: 1197720.3 | I10: =H10/2+100000 -> 698860.16 | J10: =H10/F10 -> 0.26616007 | K10: Proyectos | L10: 0.5 | M10: =16/30 -> 0.53333333
A11: =A10+1 -> 4 | B11: 2025 | C11: Bomba de Agua | D11: Pagado | F11: =439421.17/1.16 -> 378811.35 | G11: 338016.28 | H11: 50702.44 | I11: =H11/2+5000 -> 30351.22 | J11: =H11/F11 -> 0.13384615 | K11: Proyectos | L11: 1 | M11: 1
A12: =A11+1 -> 5 | B12: 2025 | C12: Uniformes personal Mpio. | D12: Pagado | F12: 101766 | G12: 72690 | H12: 24023.69 | I12: =H12/2+3000 -> 15011.845 | J12: =H12/F12 -> 0.23606794 | K12: Proyectos | L12: 1 | M12: 1
A13: =A12+1 -> 6 | B13: 2025 | C13: Regalos día de las madres | D13: Pagado | F13: 287182.75 | G13: 183400.08 | H13: =F13-G13 -> 103782.67 | I13: =H13/2 -> 51891.335 | J13: =H13/F13 -> 0.36138198 | K13: Proyectos | L13: 1 | M13: 1
A14: =A13+1 -> 7 | B14: 2025 | C14: Pavimentación de la calle las torres en Pichucalco, Chiapas. | D14: Pagado | F14: 1244484.9 | G14: 893587 | H14: 130630.24 | I14: =H14/2 -> 65315.12 | J14: =H14/F14 -> 0.10496732 | K14: Obras | L14: 1 | M14: 1
A15: =A14+1 -> 8 | B15: 2025 | C15: Luminarias | D15: Pagado | F15: 1287600 | G15: =F15-H15 -> 830032.2 | H15: 457567.8 | I15: =H15/2+40000 -> 268783.9 | J15: =H15/F15 -> 0.35536486 | L15: 1 | M15: 1
A16: =A15+1 -> 9 | B16: 2025 | C16: Láminas | D16: Pagado | F16: 81606 | G16: 33909.12 | H16: 35455.98 | I16: =H16/2+5000 -> 22727.99 | J16: =H16/F16 -> 0.43447761 | K16: Obras | L16: 1 | M16: 1
A17: =A16+1 -> 10 | B17: 2025 | C17: Pavimentación de la calle Prolongación Contreras, Pichucalco Chiapas | D17: Pagado | F17: 1180772.2 | G17: 849479 | H17: 114744.06 | I17: =H17/2 -> 57372.03 | J17: =H17/F17 -> 0.097177137 | K17: Obras | L17: 1 | M17: 1
A18: =A17+1 -> 11 | B18: 2025 | C18: Rehabilitación de guarniciones, banquetas, paso peatonal y luminaria en parque central de Pichucalco, Chiapas. | D18: Pagado | F18: 1497741.1 | G18: 1050399.1 | H18: 188404.19 | I18: =H18/2+40000 -> 134202.1 | J18: =H18/F18 -> 0.12579223 | K18: Obras | L18: 1 | M18: 1
A19: =A18+1 -> 12 | B19: 2025 | C19: Construcción de Pozos | D19: Pagado | F19: 1415122.1 | G19: 882904.22 | H19: =F19-G19 -> 532217.88 | I19: =H19/2 -> 266108.94 | J19: =H19/F19 -> 0.37609326 | K19: Obras | L19: 1 | M19: 1
A20: =A19+1 -> 13 | B20: 2025 | C20: Construcción de Tanque, línea de conducción y almacenaje | D20: Se termina la Obra para el 24 de abril | F20: 1356607.1 | G20: 952601.36 | H20: 384551.4 | I20: =H20/2 -> 192275.7 | J20: =H20/F20 -> 0.28346556 | K20: Obras | L20: 0.95 | M20: 1
A21: =A20+1 -> 14 | B21: 2025 | C21: Suministro e istalación de Bomba electrica Sumergible de 75 HP | D21: Se paga en el mes de Abril | F21: 308058.88 | G21: 235199.08 | H21: =F21-G21 -> 72859.8 | I21: =H21/2+5000 -> 41429.9 | J21: =H21/F21 -> 0.23651258 | K21: Obras | L21: 1 | M21: 0
A22: 15 | B22: 2026 | C22: Bacheo de diferentes calles del municipio | D22: Pagado | F22: 1955000 | G22: 698901.61 | H22: 556554.47 | I22: =H22/2+5000 -> 283277.23 | J22: =H22/F22 -> 0.28468259 | K22: Obras | L22: 1 | M22: 1
A23: 16 | B23: 2025 | C23: KIT de protección civil | D23: Pagado | F23: 95185.4 | G23: 54931.66 | H23: 24333.23 | I23: =H23/2+5000 -> 17166.615 | J23: =H23/F23 -> 0.25564036 | K23: Proyectos | L23: 1 | M23: 1
A24: 17 | B24: 2025 | C24: Equipamiento de dormitorios del grupo PAKAL | D24: Se paga en el mes de Abril | F24: 119968.64 | G24: 78599.17 | H24: =F24-G24 -> 41369.47 | I24: =H24/2 -> 20684.735 | J24: =H24/F24 -> 0.3448357 | K24: Proyectos | L24: 1 | M24: 1
A25: 17 | B25: 2026 | C25: Rehabilitación de Drenaje Sanitario Calle Ponciano Rojas | D25: Trabajo terminado, falta finiquito | F25: 1137944.4 | G25: 580000 | H25: 337331.24 | I25: =H25/2 -> 168665.62 | J25: =H25/F25 -> 0.29643912 | K25: Obras | L25: 1 | M25: 1
A26: 18 | B26: 2026 | C26: Rehabilitación de Drenaje Sanitario Calle Aquiles Serdan (Tectoapan) | D26: Ya se terminaron los trabajos y se metio la factura del finiquito y estimación. | F26: 855849.79 | G26: 411885.02 | H26: 267646.32 | I26: =H26/2 -> 133823.16 | J26: =H26/F26 -> 0.31272581 | K26: Obras | L26: 1 | M26: 1
A27: 19 | B27: 2026 | C27: Drenaje, banquetas, guarniciones y andador de calle Morelos | D27: Obra en sistema, en espera de fecha de contrato, monto $1.6 mdp; | K27: Obras/Licitación | L27: 0 | M27: 0
A28: 20 | B28: 2026 | C28: Drenaje los Azufres | D28: El contrato se tiene contemplado para el 01/07/26, por un monto $2.3 mdp mientras tanto se está realizando la corrida financiera para entregarse a revisión el 27-06-26 | K28: Obras/Licitación | L28: 0 | M28: 0
E29: TOTALES | F29: =SUM(F8:F27) -> 20394091 | G29: =SUM(G8:G27) -> 15318102 | H29: =SUM(H8:H27) -> 5970591.3 | I29: =SUM(I8:I27) -> 3253295.6
E31: PORCENTAJE DE UTILIDAD DE LOS PROYECTOS | H31: =H29/F29 -> 0.29276085

Sheet PLAYA
A1: INFORME PLAYA 2025/2026 | M1: =TODAY() -> 46205
A4: SOCIOS | C4: 2 | D4: APORTACIÓN | E4: 6000000 | F4: RECUPERADO | G4: =H8*M8+H9*M9+H10*M10+H11*M11+H12*M12+H13*M13+H14*M14 -> 4353853.6 | H4: UTILIDAD | I4: =H15-E4 -> 1153738.2 | K4: RECUPERADO APORTACIÓN% | L4: =G4/E4 -> 0.72564227
K5: COBRADO PROYECTOS% | L5: =AVERAGE(M8:M14) -> 0.43571429
A7: No. | B7: AÑO | C7: NOMBRE DEL PROYECTO | D7: ESTATUS | F7: POR COBRAR | G7: INVERSIÓN | H7: UTILIDAD TOTAL | I7: UTILIDAD JEFE | J7: % | K7: ÁREA ENCARGADA | L7: AVANCE FÍSICO | M7: AVANCE FINANCIERO
A8: 1 | B8: 2025 | C8: Parques y deportivos: In Hause, Nueva Esperanza, Poliforum, Forjadores, Luis Donaldo Colosio, Puerto aventura, Mario Villanueva, Leona Vicario, Grullas, 90 y Riviera Maya | D8: Ya se hizo el 13vo pago por $1,002,192.Ya se hablo con la presidenta ya nos va a hacer un plan de pagos | F8: =21344142.99/1.16 -> 18400123 | G8: =15948348.03 -> 15948348 | H8: 4814213.6 | I8: =H8/3 -> 1604737.9 | J8: =H8/F8 -> 0.26164029 | K8: Obras/Tesorería | L8: 1 | M8: 0.6
A9: 2 | B9: 2025 | C9: Rehabilitación y mantenimiento de 15 Parques en playa del Carmen. | D9: (Parques al 100%) Bella Vista, Fenix Forjadores, Mundo habitad, NicteHa, Natura,Zazil ha, Palmas 1, Villa Mar, Villas Riviera, La Guadalupana, Peten, Pto. Aventuras, Lol- Be, Cristo Rey, Riviera Maya. Se reprogramó el pago en el primer mes de enero 2026 | F9: =2691748.5/1.16 -> 2320472.8 | G9: 1681538.1 | H9: 697410.68 | I9: =H9/3 -> 232470.23 | J9: =H9/F9 -> 0.3005468 | K9: Obras | L9: 1 | M9: 0
A10: 3 | B10: 2025 | C10: Proyecto Eléctrico de Av. 10 en el centro de Playa del Carmen. | D10: Proyecto Terminado y pagado | F10: 3823739 | G10: 1814481.7 | H10: 1261852 | I10: =H10/3 -> 420617.33 | J10: =H10/F10 -> 0.33000475 | K10: Obras | L10: 1 | M10: 1
A11: 4 | B11: 2026 | C11: Proyecto de Implementación de Sistema de Paneles Solares en Ayuntamientos | D11: Pendiente | K11: Obras | L11: 0 | M11: 0
A12: 5 | B12: 2026 | C12: Iluminación en Centro de Salud | D12: Proyecto Terminado pendiente de Pago | F12: =1157644.17/1.16 -> 997969.11 | G12: 571190.39 | H12: 321433.63 | I12: =H12/3 -> 107144.54 | J12: 0.32 | K12: Obras | L12: 1 | M12: 0.45
A13: 6 | B13: 2026 | C13: Proyecto de Infraestructura eléctrica en Av. 10 | D13: Obra Terminada y pagado | F13: 181486.07 | G13: 102112.3 | H13: 58828.3 | I13: =H13/3 -> 19609.433 | J13: 0.32 | K13: Obras | L13: 1 | M13: 1
A14: 7 | B14: 2026 | C14: Infraestructura Eléctrica Cancha de Tenis (Proyecto personal del Arq. Regalado) | D14: Obra Terminada pendiente de pago | F14: =410172.1/1.16 -> 353596.64 | K14: Obras | L14: 1 | M14: 0
E15: TOTALES | F15: =SUM(F8:F14) -> 26077387 | G15: =SUM(G8:G14) -> 20117670 | H15: =SUM(H8:H14) -> 7153738.2 | I15: =SUM(I8:I14) -> 2384579.4
E17: PORCENTAJE DE UTILIDAD DE LOS PROYECTOS | H17: =H15/F15 -> 0.27432727

Sheet TUXTLA
A1: INFORME TUXTLA 2025/2026 | M1: =TODAY() -> 46205
A4: SOCIOS | C4: 1 | D4: APORTACIÓN | E4: 3500000 | F4: RECUPERADO | G4: =I8*M8+I9*M9+I10*M10+I11*M11+I12*M12+I13*M13 -> 4536746.5 | H4: UTILIDAD | I4: =I15-E4 -> 5657491.7 | K4: RECUPERADO APORTACIÓN% | L4: =G4/E4 -> 1.2962133
K5: COBRADO PROYECTOS% | L5: =AVERAGE(M8:M13) -> 0.775
A7: No. | B7: AÑO | C7: NOMBRE DEL PROYECTO | D7: ESTATUS | F7: POR COBRAR | G7: INVERSIÓN | H7: UTILIDAD TOTAL | I7: UTILIDAD JEFE | J7: % | K7: ÁREA ENCARGADA | L7: AVANCE FÍSICO | M7: AVANCE FINANCIERO
A8: 1 | B8: 2025 | C8: Uniformes | D8: Se pagan en julio | F8: =959679.24/1.16 -> 827309.69 | G8: 714308.3 | H8: 245370.94 | I8: 147222.56 | J8: =H8/F8 -> 0.29658898 | K8: Proyectos | L8: 1 | M8: 0.7
A9: 2 | B9: 2025 | C9: Despensas | D9: PAGADO | F9: 2434370 | G9: 1698000 | H9: 429159 | I9: =H9*0.7 -> 300411.3 | J9: =H9/F9 -> 0.17629161 | K9: Proyectos | L9: 1 | M9: 1
A10: =A9+1 -> 3 | B10: 2025 | C10: 10 Ambulancias | D10: PAGADO | F10: 17580900 | G10: 12174502 | H10: 5222589.3 | I10: 3510702.9 | J10: =H10/F10 -> 0.29706041 | K10: Proyectos | L10: 1 | M10: 1
A11: =A10+1 -> 4 | B11: 2025 | C11: Construcción de muros de contención, solicitados por Protección Civil del Estado de Chiapas | D11: PAGADO | F11: =3499020.35/1.16 -> 3016396.9 | G11: 2139835.1 | H11: 876561.73 | I11: =H11*0.7 -> 613593.21 | J11: =H11/F11 -> 0.29059894 | K11: Obras | L11: 1 | M11: 1
A12: =A11+1 -> 5 | B12: 2025 | C12: Baterias EPCOM | D12: se paga en julio | F12: 49590 | G12: 29300 | H12: 13508.74 | I12: =H12*0.7 -> 9456.118 | J12: =H12/F12 -> 0.27240855 | K12: Proyectos | L12: 1 | M12: 0.95
A13: =A12+1 -> 6 | B13: 2026 | C13: 16 Ambulancias y Obra | D13: El día de hoy van a ver em tema de la obra y estam semana igual el tema de las ambulancias | F13: =28155520/1.16 -> 24272000 | G13: 22496000 | H13: 5492431.4 | I13: 4576105.6 | J13: 0.2 | K13: RM/Proyectos | L13: 0 | M13: 0
B14: 2026 | C14: Proyecto Muros de Contención en Tapachula Chiapas | D14: se está realizando la corrida Financiera correspondiente se envía a revisión para autorización del día 27-06-26 | F14: 9611455 | K14: obras | L14: 0 | M14: 0
E15: TOTALES | F15: =SUM(F8:F13) -> 48180566 | G15: =SUM(G8:G13) -> 39251945 | H15: =SUM(H8:H13) -> 12279621 | I15: =SUM(I8:I13) -> 9157491.7
D17: PORCENTAJE DE UTILIDAD DE LOS PROYECTOS | H17: =H15/F15 -> 0.25486668

Sheet TEAPA
A1: INFORME TEAPA 2025/2026 | M1: =TODAY() -> 46205
A4: SOCIOS | C4: 1 | D4: APORTACIÓN | E4: 5240000 | F4: RECUPERADO | G4: =H8*M8+H9*M9+H10*M10+H11*M11+H12*M12+H13*M13+H14*M14+H15*M15+H16*M16+H18*M18+H17*M17+H20*M20+H22*M22+H23*M23+H19*M19+H21*M21+H24*M24+H25*M25+H26*M26+H27*M27+H28*M28 -> 6934692.1 | H4: UTILIDAD | I4: =H31-E4 -> 4986253.4 | K4: RECUPERADO APORTACIÓN% | L4: =G4/E4 -> 1.3234145
K5: COBRADO PROYECTOS% | L5: =AVERAGE(M8:M26) -> 0.92050844
A7: No. | B7: AÑO | C7: NOMBRE DEL PROYECTO | D7: ESTATUS | F7: POR COBRAR | G7: INVERSIÓN | H7: UTILIDAD TOTAL | I7: UTILIDAD JEFE | J7: % | K7: ÁREA ENCARGADA | L7: AVANCE FÍSICO | M7: AVANCE FINANCIERO
A8: 1 | B8: 2025 | C8: Arrendamiento de Camiones de Basura | D8: Se lleva pagado 16 meses de 32 | F8: =16704000/1.16 -> 14400000 | G8: 7301889.7 | H8: 4509134.3 | I8: =H8/2 -> 2254567.1 | J8: =H8/F8 -> 0.31313432 | K8: Recursos Materiales | L8: =16/32 -> 0.5 | M8: =7051108.65/F8 -> 0.48966032
A9: =A8+1 -> 2 | B9: 2025 | C9: Venta de pintura | D9: Terminado y pagado | F9: =47352.8/1.16 -> 40821.379 | G9: 30856.5 | H9: =F9-G9 -> 9964.8793 | I9: =H9/2 -> 4982.4397 | J9: =H9/F9 -> 0.24410932 | K9: Recursos Materiales | L9: 1 | M9: 1
A10: 3 | B10: 2025 | C10: Venta de Radios | D10: Terminado y pagado | F10: =107810.92/1.16 -> 92940.448 | G10: 80114.99 | H10: 26294.39 | I10: =H10/2 -> 13147.195 | J10: =H10/F10 -> 0.28291654 | K10: Recursos Materiales | L10: 1 | M10: 1
A11: =A10+1 -> 4 | B11: 2025 | C11: Arrendamientos de Vehìculos Admón 13 unidades hasta sept y 9 unidades 2 meses | D11: Terminado y pagado | F11: ='[1]Hoja1 (2)'!$L$44*7+'[1]Hoja1 (2)'!$L$70*2 -> 3148245.8 | G11: =F11*0.8 -> 2518596.6 | H11: =F11*0.2 -> 629649.16 | I11: =H11/2 -> 314824.58 | J11: =H11/F11 -> 0.2 | K11: Recursos Materiales | L11: 1 | M11: 1
A12: 5 | B12: 2025 | C12: Luminarias | D12: Terminado y pagado | F12: =490778.61/1.16 -> 423085.01 | G12: 151407.84 | H12: 208869.96 | I12: =H12/2 -> 104434.98 | J12: =H12/F12 -> 0.4936832 | K12: Recursos Materiales | L12: 1 | M12: 1
A13: =A12+1 -> 6 | B13: 2025 | C13: Emulsión catatónica | D13: Terminado y pagado | F13: =229970/1.16 -> 198250 | G13: 151109.86 | H13: 78860.14 | I13: =H13/2 -> 39430.07 | J13: =H13/F13 -> 0.39778129 | K13: Recursos Materiales | L13: 1 | M13: 1
A14: 7 | B14: 2025 | C14: Venta de llantas | D14: Terminado y pagado | F14: =107448.48/1.16 -> 92628 | G14: 0 | H14: 39622.54 | I14: =H14/2 -> 19811.27 | J14: =H14/F14 -> 0.42775986 | K14: Recursos Materiales | L14: 1 | M14: 1
A15: =A14+1 -> 8 | B15: 2025 | C15: Luminarias | D15: Terminado y pagado | F15: =2000000/1.16 -> 1724137.9 | G15: 1052714.6 | H15: 381285.37 | I15: =H15/2 -> 190642.68 | J15: =H15/F15 -> 0.22114551 | K15: Obras | L15: 1 | M15: 1
A16: 9 | B16: 2025 | C16: 2 estaquitas y 1 virtus | D16: Terminado y pagado | F16: =H16*1.3 -> 1283634.4 | G16: =F16*0.6 -> 770180.62 | H16: 987411.05 | I16: =H16/2 -> 493705.53 | J16: =H16/F16 -> 0.76923077 | K16: Recursos Materiales | L16: 1 | M16: 1
A17: =A16+1 -> 10 | B17: 2025 | C17: Teapa Pavimentación, drenaje, guarniciones y banquetas en brisas del puyacatengo (Obra agua potable) | D17: Terminada la obra 100% y pagada | F17: =223708.47/1.16 -> 192852.13 | G17: 126329.91 | H17: 69772.92 | I17: 34886.46 | J17: =H17/F17 -> 0.36179492 | K17: Obras | L17: 1 | M17: 1
A18: 11 | B18: 2025 | C18: Teapa Pavimentación, drenaje, guarniciones y banquetas en brisas del puyacatengo (Obra drenaje) | D18: Terminada la obra 100% y pagada | F18: =570823.5/1.16 -> 492089.22 | G18: 310634.21 | H18: 183128.12 | I18: =H18/2 -> 91564.06 | J18: =H18/F18 -> 0.37214414 | K18: Obras | L18: 1 | M18: 1
A19: =A18+1 -> 12 | B19: 2025 | C19: Teapa Pavimentación, drenaje, guarniciones y banquetas en brisas del puyacatengo (Alumbrado) | D19: Terminada la obra 100% y pagada | F19: 128019.23 | G19: =F19-H19 -> 96014.423 | H19: =F19*0.25 -> 32004.807 | I19: =H19/2 -> 16002.404 | J19: =H19/F19 -> 0.25 | K19: Obras | L19: 1 | M19: 1
A20: 13 | B20: 2025 | C20: Teapa Pavimentación, drenaje, guarniciones y banquetas en brisas del puyacatengo (Banquetas y guarniciones) | D20: Terminada la obra 100% y pagada | F20: =380094.75/1.16 -> 327667.89 | G20: =F20*0.7 -> 229367.52 | H20: =F20-G20 -> 98300.366 | I20: =H20/2 -> 49150.183 | J20: =H20/F20 -> 0.3 | K20: Obras | L20: 1 | M20: 1
A21: =A20+1 -> 14 | B21: 2025 | C21: Teapa Pavimentación, drenaje, guarniciones y banquetas en brisas del puyacatengo (Pavimento) | D21: Terminada la obra 100% y pagada | F21: 807015.12 | G21: =F21-H21 -> 605261.34 | H21: =F21*0.25 -> 201753.78 | I21: =H21/2 -> 100876.89 | J21: =H21/F21 -> 0.25 | K21: Obras | L21: 1 | M21: 1
A22: 15 | B22: 2025 | C22: Obra Cancha Tejería | D22: TERMINADA Y PAGADO | F22: 2479374.8 | G22: 1521616.7 | H22: =F22-G22 -> 957758.05 | I22: =H22/2 -> 478879.03 | J22: =H22/F22 -> 0.38629015 | K22: Obras | L22: 1 | M22: 1
A23: =A22+1 -> 16 | B23: 2025 | C23: Renta de Planta Electrica | D23: Entregado, pendiente de pago | F23: 21521.34 | G23: 18561.16 | H23: =F23-G23 -> 2960.18 | I23: =H23/2 -> 1480.09 | J23: =H23/F23 -> 0.13754627 | K23: Recursos Materiales | L23: 1 | M23: 0
A24: 17 | B24: 2025 | C24: Sistema de microfonos | D24: Entregado, pendiente de pago | F24: 33450 | G24: 21000 | H24: 9064.63 | I24: =H24/2 -> 4532.315 | J24: =H24/F24 -> 0.27099043 | K24: Recursos Materiales | L24: 1 | M24: 1
A25: =A24+1 -> 18 | B25: 2025 | C25: Rehabilitacion de Red de Alcantarillado (Pluvial) en el municipio de Teapa, Ciudad de Teapa, Colonia La Sierra Sección Ríos, Calles Río Tulijá y Rio Puxcatan | D25: Terminada la obra 100% y pagada | F25: 756023.25 | G25: 585545.9 | H25: 165802.98 | I25: =H25/2 -> 82901.49 | J25: =H25/F25 -> 0.21930937 | K25: Obras | L25: 1 | M25: 1
A26: 19 | B26: 2025 | C26: Rehabilitacion de Red de Drenaje Sanitario en el municipio de Teapa, Ciudad de Teapa, Colonia La Sierra Sección Ríos, Calles Río Tulijá y Rio Puxcatan. | D26: Terminada la obra 100% y pagada | F26: 585168.52 | G26: 455181.06 | H26: 119323.64 | I26: =H26/2 -> 59661.82 | J26: =H26/F26 -> 0.20391329 | K26: Obras | L26: 1 | M26: 1
A27: =A26+1 -> 20 | B27: 2025 | C27: Rehabilitacion de Banquetas y Guarniciones en el municipio de Teapa, Ciudad de Teapa, Colonia La Sierra Sección Ríos, Calles Río Tulijá y Rio Puxcatan. | D27: Terminada la obra 100% y pagada | F27: =463416.98/1.16 -> 399497.4 | G27: 255421.5 | H27: 113420.73 | I27: =H27/2 -> 56710.365 | J27: =H27/F27 -> 0.28390856 | K27: Obras | L27: 1 | M27: 1
A28: 21 | B28: 2025 | C28: Pavimento Hidráulico en el Municipio de Teapa, Ciudad de Teapa, Colonia La Sierra Sección Ríos, Calles Río Tulijá y Río Puxcatan. | D28: Terminada la obra 100% y pagada | F28: =1660622.59/1.16 -> 1431571.2 | G28: 1102965.1 | H28: 414460.4 | I28: =H28/2 -> 207230.2 | J28: =H28/F28 -> 0.28951435 | K28: Obras | L28: 1 | M28: 1
A29: 22 | B29: 2026 | C29: 2 estaquitas y 1 virtus | D29: Arrendamiento | F29: =H29*1.3 -> 1283634.4 | G29: =F29*0.6 -> 770180.62 | H29: 987411.05 | I29: =H29/2 -> 493705.53 | J29: =H29/F29 -> 0.76923077 | K29: Recursos Materiales | L29: =5/12 -> 0.41666667 | M29: =3/12 -> 0.25
A30: 23 | B30: 2026 | C30: Las Delicias Drenaje sanitario, guarniciones y banquetas y pavimento. | D30: Se está realizando la corrida financiera y será entregada para su revisión el próximo lunes 29-06-26 con un monto total aun en revisión de $2,783,961.00 | K30: Obras/Licitación
E31: TOTALES | F31: =SUM(F8:F30) -> 30341627 | G31: =SUM(G8:G30) -> 18154950 | H31: =SUM(H8:H30) -> 10226253 | I31: =SUM(I8:I30) -> 5113126.7
E33: PORCENTAJE DE UTILIDAD DE LOS PROYECTOS | H33: =H31/F31 -> 0.33703708

Sheet TULUM
A1: INFORME TULUM 2025/2026 | M1: =TODAY() -> 46205
A4: SOCIOS | C4: - | D4: APORTACIÓN | E4: 1500000 | F4: RECUPERADO | G4: =H9 -> 0 | H4: PENDIENTE | I4: =E4-G4 -> 1500000 | K4: RECUPERADO APORTACIÓN% | L4: =G4/E4 -> 0
K5: COBRADO PROYECTOS% | L5: =M8 -> 0
A7: No. | B7: AÑO | C7: NOMBRE DEL PROYECTO | D7: ESTATUS | F7: POR COBRAR | G7: INVERSIÓN | H7: UTILIDAD TOTAL | I7: UTILIDAD JEFE | J7: % | K7: ÁREA ENCARGADA | L7: AVANCE FÍSICO | M7: AVANCE FINANCIERO
A8: 1 | B8: 2025 | C8: Tulum luminarias | D8: Pendiente | K8: Proyectos | L8: 0 | M8: 0
E9: TOTALES | F9: =SUM(F8) -> 0 | G9: =SUM(G8) -> 0 | H9: =SUM(H8) -> 0 | I9: =SUM(I8) -> 0
E11: PORCENTAJE DE UTILIDAD DE LOS PROYECTOS | H11: -

Sheet XOCHI
A1: INFORME XOCHI 2025/2026 | M1: =TODAY() -> 46205
A4: SOCIOS | C4: - | D4: APORTACIÓN | E4: 4000000 | F4: RECUPERADO | G4: =I8*M8+I9*M9+I10*M10+I11*M11 -> 6846881.5 | H4: UTILIDAD | I4: =I12-E4 -> 24903412 | K4: RECUPERADO APORTACIÓN% | L4: =G4/E4 -> 1.7117204
K5: COBRADO PROYECTOS% | L5: =AVERAGE(M8:M11) -> 0.3325
A7: No. | B7: AÑO | C7: NOMBRE DEL PROYECTO | D7: ESTATUS | F7: POR COBRAR | G7: INVERSIÓN | H7: UTILIDAD TOTAL | I7: UTILIDAD JEFE | J7: % | K7: ÁREA ENCARGADA | L7: AVANCE FÍSICO | M7: AVANCE FINANCIERO
A8: 1 | B8: 2025 | C8: 6,000 Luminarias | D8: ya se ingresaron facturas, en espera de pagos correspondientes, los contratos ascienden a $39,994,841.92 hicieron 4 pagos por el monto de $21,065,101.42 | F8: =65156378.72/1.16 -> 56169292 | G8: 28945016 | H8: 17919784 | I8: =H8 -> 17919784 | J8: =H8/F8 -> 0.3190317 | K8: Recursos Materiales | L8: 1 | M8: 0.33
A9: 2 | B9: 2025 | C9: Alimentos A CENDIS | D9: concluido | F9: =2432129.5+970530+721085.5+1066687.5 -> 5190432.5 | G9: =757192.13+485727.64+627413.49+1722737.14 -> 3593070.4 | H9: =171950.13+439967.66+133595.32+187839.55 -> 933352.66 | I9: =H9 -> 933352.66 | J9: =I9/F9 -> 0.17982175 | K9: Recursos Materiales | L9: 1 | M9: 1
A10: 3 | B10: 2026 | C10: Video Vigilancia Alcaldia | D10: Ya se metio la fact en espera del pago | F10: 19992983 | G10: 6879100 | H10: 9116922.1 | I10: =H10 -> 9116922.1 | J10: =H10/F10 -> 0.4560061 | K10: Recursos Materiales | L10: 0.98 | M10: 0
A11: =A10+1 -> 4 | B11: 2026 | C11: Alimentos A CENDIS | D11: Ya se tiene el contrato | F11: =2432129.5+970530+721085.5+1066687.5 -> 5190432.5 | G11: =757192.13+485727.64+627413.49+1722737.14 -> 3593070.4 | H11: =171950.13+439967.66+133595.32+187839.55 -> 933352.66 | I11: =H11 -> 933352.66 | J11: =I11/F11 -> 0.17982175 | K11: Recursos Materiales | L11: 0.5 | M11: 0
E12: TOTALES | F12: =SUM(F8:F11) -> 86543140 | G12: =SUM(G8:G11) -> 43010257 | H12: =SUM(H8:H11) -> 28903412 | I12: =SUM(I8:I11) -> 28903412
E14: PORCENTAJE DE UTILIDAD DE LOS PROYECTOS | H14: =H12/F12 -> 0.33397693

Sheet VERACRUZ
A1: INFORME VERACRUZ 2025/2026 | N1: =TODAY() -> 46205
A4: SOCIOS | C4: - | D4: APORTACIÓN | E4: =G47 -> 13790000 | G4: RECUPERADO | H4: =J14*N14+J13*N13+J33*N33+J41*N41 -> 2067853.9 | I4: PENDIENTE | J4: =E4-H4 -> 11722146 | K4: RECUPERADO APORTACIÓN% | M4: =H4/E4 -> 0.14995315
K5: COBRADO PROYECTOS% | M5: =AVERAGE(N8:N46) -> 0.1303232
A7: No. | B7: AÑO | C7: NOMBRE DEL PROYECTO | D7: ESTATUS | E7: OBSERVACIONES | G7: APORTACIÓN | H7: PROYECTOS POR COBRAR | I7: INVERSIÓN | J7: UTILIDAD JEFE | K7: % | L7: ÁREA ENCARGADA | M7: AVANCE FÍSICO | N7: AVANCE FINANCIERO
A8: 1 | B8: 2026 | C8: Alvarado, Veracruz (pérdido) | D8: Se le mostraron las luminarias y se tuvo una junta sobre el tema de Vigilancia, ya se esta preparando la cotización de acuerdo al levantamiento para el 8 o 9 de abril | E8: PENDIENTE | F8: PENDIENTE | G8: 3000000 | L8: Proyectos
A9: 2 | B9: 2026 | C9: Banderilla, Veracruz | D9: Recolector de basura seminuevo de 21 yardas | E9: CANCELADO | F9: CANCELADO | H9: 2580000 | I9: 1720000 | J9: 735644 | K9: =J9/H9 -> 0.28513333 | L9: Proyectos
A10: 3 | B10: 2026 | C10: Camaron | D10: luminarias | E10: La 1era quincena de agosto paga | F10: Paga en agosto | H10: 986000 | I10: 628140 | J10: 287570 | K10: 0.29 | L10: Proyectos | M10: 1 | N10: 0
A11: 4 | B11: 2026 | C11: Carlos A. Carrillo, Veracruz | D11: Se entregaron 25 luminarias electricas (LPFO-50w) de 6,000 LMNS y 25 luminarias electricas (LPFC-100W)) de 12,000 LMNS. | E11: Se tiene cita esta semana para ver el tema del pago | F11: En junio paga | G11: 160000 | H11: 139490 | I11: 66120 | J11: 54386.29 | K11: =J11/H11 -> 0.38989383 | L11: Proyectos | M11: 1 | N11: 0
A12: 5 | B12: 2026 | C12: Catemaco, Veracruz | D12: Ingeniería Electrica en el Malecón con 195 Luminarias (En proceso licitación); Se instalaron 18 Luminarias Solares LS3 solicitadas y se entregó proyecto de Puerta monumental de Acceso | E12: El 30 de junio pagan | F12: Se paga en junio | H12: 3476903.4 | I12: 1721757 | J12: 1234088.8 | K12: =J12/H12 -> 0.35493904 | L12: Proyectos | M12: 1 | N12: 0
A13: 6 | B13: 2026 | C13: Catemaco, Veracruz | D13: Venta de ambulancia, entregada el 25 de febrero y en espera de un recolector y una pipa | E13: Entregada | F13: PAGADA | H13: 2272000 | I13: 1317600 | J13: 647881.93 | K13: =J13/H13 -> 0.2851593 | L13: Proyectos | M13: 1 | N13: 1
A14: 7 | B14: 2026 | C14: Chinameca, Veracruz | D14: Venta de ambulancia, entregada el 27 de diciembre | E14: La otra parte se paga en agosto | F14: Ya pagaron una parte | H14: 1888094.4 | I14: 1307734.2 | J14: 501168.4 | K14: =J14/H14 -> 0.26543609 | L14: Proyectos | M14: 1 | N14: =629364.8/H14 -> 0.33333334
A15: 8 | B15: 2026 | C15: Comapa, Veracruz (se perdió) | D15: La primera semana de abril se va a platicar con ellos para ver que se les puede vender | E15: PENDIENTE | F15: PENDIENTE | G15: 1000000 | L15: Proyectos
A16: 9 | B16: 2026 | C16: Cosautlán, Veracruz | D16: Recolector de basura seminuevo de 21 yardas | E16: CANCELADO | F16: CANCELADO | H16: 2580000 | I16: 1720000 | J16: 735644 | K16: =J16/H16 -> 0.28513333 | L16: Proyectos
A17: 10 | B17: 2026 | C17: Cotaxtla, Veracruz | D17: Recolector de basura seminuevo de 21 yardas | E17: CANCELADO | F17: CANCELADO | H17: 2580000 | I17: 1720000 | J17: 735644 | K17: =J17/H17 -> 0.28513333 | L17: Proyectos
A18: 11 | B18: 2026 | C18: Cuitláhuac, Veracruz | D18: Esta pendiente | E18: PENDIENTE | F18: PENDIENTE | G18: 800000 | L18: Proyectos
A19: 12 | B19: 2026 | C19: Dirigente de Morena | D19: Esta ayudando a ver a otros municipios | E19: PENDIENTE | F19: PENDIENTE | G19: 200000 | L19: Proyectos
A20: 13 | B20: 2026 | C20: Ixhuatlán del Sureste, Veracruz | D20: Recolector de basura seminuevo de 14 yardas | E20: Después de pagar la ambulancia paga el recolector | F20: En julio | H20: 2580000 | I20: 1720000 | J20: 735644 | K20: =J20/H20 -> 0.28513333 | M20: 1 | N20: 0
A21: 14 | B21: 2026 | C21: Ixhuatlán del Sureste, Veracruz | D21: Apenas nos va a hacer un pedido de 500 luminarias | E21: En junio hacen el pedido | F21: En espera de autorizacion | G21: 300000 | L21: Proyectos | M21: 0 | N21: 0
A22: 15 | B22: 2026 | C22: Ixhuatlán del Sureste, Veracruz | D22: Se entrego la ambulancia | E22: Se paga en junio | F22: SE ABONARON $500,000 | H22: 2200000 | I22: 1307734.2 | J22: 540142.85 | K22: =J22/H22 -> 0.24551948 | L22: Proyectos | M22: 1 | N22: =500000/H22 -> 0.22727273
A23: 16 | B23: 2026 | C23: Nanchital de Lázaro Cárdenas del Río, Veracruz | D23: Nos pidio cotización de luminarias | E23: En 2 meses nos avisa | F23: PENDIENTE | G23: 300000 | L23: Proyectos
A24: 17 | B24: 2026 | C24: Pajapan, Veracruz | D24: En espera de ver tema de luminarias y va a pedir una pipa o un volteo | E24: En espera de recibir el pedido | F24: En espera de autorizacion | G24: 500000 | L24: Proyectos | M24: 0 | N24: 0
A25: 18 | B25: 2026 | C25: Paso de Ovejas | D25: Se instalaron 20 luminarias para llevar a cabo la inauguración (LPF-100W) | E25: En espera del pago y se esta viendo acepten un camión | F25: En espera de autorizacion | H25: 204965.23 | I25: 105413.72 | J25: 71189.14 | K25: =J25/H25 -> 0.34732301 | L25: Proyectos | M25: 1
A26: 19 | B26: 2026 | C26: Paso de Ovejas | D26: Pipa, camión y volteo. | E26: CANCELADO | F26: CANCELADO | H26: =1920000+1950000+2350000 -> 6220000 | I26: 4148000 | J26: 1678006 | K26: =J26/H26 -> 0.26977588 | L26: Proyectos | M26: 1 | N26: 0
A27: 20 | B27: 2026 | C27: Poza Rica de Hidalgo, Veracruz | D27: Se les dio $825,000 adicional para gestionar abogados, etc… | E27: PENDIENTE | F27: PENDIENTE | G27: 3900000 | L27: Proyectos
A28: 21 | B28: 2026 | C28: Rafael Lucio, Veracruz | D28: Recolector de basura seminuevo de 14 yardas | E28: CANCELADO | F28: CANCELADO | H28: 2380000 | I28: 1438000 | J28: 818364 | K28: =J28/H28 -> 0.34385042 | L28: Proyectos | M28: 0 | N28: 0
A29: 22 | B29: 2026 | C29: Saltabarranca, Veracruz | D29: Se solicitaron 300 Luminarias modelo LPF-70W 12,600 Lúmenes. Ya fueron entregadas en su totalidad. Acaba de pedir 100 luminarias mas | E29: En junio paga | F29: Se esta viendo lo del pago | G29: 430000 | H29: 870000 | I29: 495900 | J29: 323031 | K29: =J29/H29 -> 0.3713 | L29: Proyectos | M29: 1 | N29: 0
A30: 23 | B30: 2026 | C30: Santiago Tuxtla II, Veracruz | D30: En proceso de Termino de los trabajos | E30: En junio paga la mitad y en agosto la otra mitad | F30: Se esta viendo lo del pago | H30: 1851441.2 | I30: 907658.24 | J30: 665770.86 | L30: Proyectos | M30: 0.9 | N30: 0
A31: 24 | B31: 2026 | C31: Santiago Tuxtla, Veracruz | D31: Se está atendiendo 10 Luminarias reportadas para garantías. | E31: En junio paga la mitad y en agosto la otra mitad | F31: Se esta viendo lo del pago | G31: 2000000 | H31: 4946886 | I31: 2356223.9 | J31: 1825100.7 | K31: =J31/H31 -> 0.36893932 | L31: Proyectos | M31: 0.9 | N31: 0
A32: 25 | B32: 2026 | C32: Sayula, Veracruz | D32: Recolector de basura seminuevo de 21 yardas | E32: CANCELADO | F32: CANCELADO | H32: 2580000 | I32: 1720000 | J32: 735644 | K32: =J32/H32 -> 0.28513333 | L32: Proyectos | M32: 0 | N32: 0
A33: 26 | B33: 2026 | C33: Soledad de Doblado | D33: Venta de ambulancia, entregada el 03 de marzo, la entregaron a Soledad de doblado. Se le dieron $100,000 del reporte de las luminarias | E33: PAGADA | F33: PAGADA | H33: 2335000 | I33: 1275450.2 | J33: 618874.32 | K33: =J33/H33 -> 0.26504254 | L33: Proyectos | M33: 1 | N33: 1
A34: 27 | B34: 2026 | C34: Soledad de Doblado | D34: Se le vendieron 600 luminarias electricas de 12,000 LMN | E34: Se paga en junio | F34: Se esta viendo lo del pago | H34: 1997520 | I34: 991800 | J34: 736567.08 | K34: =J34/H34 -> 0.36874078 | L34: Proyectos | M34: 1 | N34: 0
A35: 28 | B35: 2026 | C35: Soledad de Doblado | D35: Urban 14 `pasajeros | E35: Esta semana nos dicen si la aceptan | F35: PENDIENTE | H35: 1320000 | I35: 784900 | J35: 459566 | K35: =J35/H35 -> 0.34815606 | L35: Proyectos | M35: 1 | N35: 0
A36: 29 | B36: 2026 | C36: Soteapan, Veracruz | D36: Pidieron un compactador | E36: PENDIENTE | F36: PENDIENTE | G36: 300000 | L36: Proyectos
A37: 30 | B37: 2026 | C37: Tampico, Alto | D37: Venta de ambulancia, se entrega el 7 de abril. | E37: CANCELADO | F37: CANCELADO | H37: 1900000 | I37: 1275450.2 | J37: 542426.85 | K37: =J37/H37 -> 0.28548782 | L37: Proyectos
A38: 31 | B38: 2026 | C38: Tatahuicapan, Veracruz | D38: Compactador | E38: En junio pagan | F38: Se esta viendo lo del pago | G38: 300000 | H38: 235631.28 | I38: 116010.44 | J38: 84268.1 | K38: =J38/H38 -> 0.35762697 | L38: Proyectos | M38: 1 | N38: 0
A39: 32 | B39: 2026 | C39: Texistepec, Veracruz | D39: Recolector de basura seminuevo de 21 yardas | E39: CANCELADO | F39: CANCELADO | H39: 2580000 | I39: 1720000 | J39: 735644 | K39: =J39/H39 -> 0.28513333 | L39: Proyectos
A40: 33 | B40: 2026 | C40: Tierra Blanca, Veracruz | D40: El jueves nos confirma el pedido de luminarias | E40: PENDIENTE | F40: PENDIENTE | G40: 200000 | L40: Proyectos
A41: 34 | B41: 2026 | C41: Xico, Veracruz | D41: Compactador | E41: Se paga en agosto la otra parte | F41: MITAD PAGADA | H41: =2500000+1908000 -> 4408000 | I41: =1762988+1345512 -> 3108500 | J41: =483900.72+634041.28 -> 1117942 | K41: =J41/H41 -> 0.25361661 | L41: Proyectos | M41: 1 | N41: =2500000/H41 -> 0.56715064
A42: 35 | B42: 2026 | C42: Xico, Veracruz | D42: Rodillo | E42: PENDIENTE | F42: PENDIENTE | H42: 4502880 | I42: 2294000 | J42: 1345933.5 | K42: =J42/H42 -> 0.29890503 | L42: Proyectos
A43: 36 | B43: 2026 | C43: Xico, Veracruz | D43: Se entregaron 30 solares con brazos y 297 electricas de 6,000 LMS con accesorios para instalación | E43: En julio pagan | F43: En julio pagan | H43: 1914406 | I43: 1007425.1 | J43: 652440.64 | K43: =J43/H43 -> 0.34080578 | L43: Proyectos | M43: 1 | N43: 0
...

Sheet ZITACUARO
A1: INFORME ZITACUARO 2025/2026 | M1: =TODAY() -> 46205
A4: SOCIOS | C4: 1 | D4: APORTACIÓN | E4: 2000000 | F4: RECUPERADO | G4: =H8*M8+H9*M9+H11*M11+H10*M10 -> 411623.56 | H4: PENDIENTE | I4: =E4-G4 -> 1588376.4 | K4: RECUPERADO APORTACIÓN% | L4: =G4/E4 -> 0.20581178
K5: COBRADO PROYECTOS% | L5: =AVERAGE(M8:M11) -> 0.4244023
A7: No. | B7: AÑO | C7: NOMBRE DEL PROYECTO | D7: ESTATUS | F7: POR COBRAR | G7: INVERSIÓN | H7: UTILIDAD TOTAL | I7: UTILIDAD JEFE | J7: % | K7: ÁREA ENCARGADA | L7: AVANCE FÍSICO | M7: AVANCE FINANCIERO
A8: 1 | B8: 2025 | C8: Zitácuaro Luminarias | D8: Terminado y pagado | F8: =1075320/1.16 -> 927000 | G8: 522000 | H8: 338256 | I8: =H8 -> 338256 | J8: =H8/F8 -> 0.3648932 | K8: Obras | L8: 1 | M8: 1
A9: 2 | B9: 2025 | C9: Luminarias | D9: Se pagaron solo 250 luminarias ($456,170), faltan 50, de lo cual no hay fact | F9: =522000 -> 522000 | G9: 364000 | H9: 105170 | I9: =H9 -> 105170 | J9: =H9/F9 -> 0.2014751 | K9: Obras | L9: 1 | M9: =(147000+108576*2)/F9 -> 0.6976092
A10: 3 | B10: 2025 | C10: Luminarias | D10: Se entregaron 300 luminarias esta semana, se pagará en 2026. ($547,404.00 con IVA). Sigue pendiente la facturación de estas luminarias | F10: =547500 -> 547500 | G10: 348000 | H10: 128508.5 | I10: =H10 -> 128508.5 | J10: =I10/F10 -> 0.23471872 | K10: Obras | L10: 1 | M10: 0
A11: 4 | B11: 2026 | C11: Equipo de Cómputo | D11: Ya nos autorizaron un proyecto de papeleria por $1.3MDP. Estamos en espera de que se entregue | F11: 1115591.4 | G11: 676116 | H11: 378117.87 | I11: =H11 -> 378117.87 | J11: =I11/F11 -> 0.33893939 | K11: Obras | L11: 0.5 | M11: 0
E12: TOTALES | F12: =SUM(F8:F11) -> 3112091.4 | G12: =SUM(G8:G11) -> 1910116 | H12: =SUM(H8:H11) -> 950052.37 | I12: =SUM(I8:I11) -> 950052.37
E14: PORCENTAJE DE UTILIDAD DE LOS PROYECTOS | H14: =H12/F12 -> 0.30527779

Sheet GENERAL
A1: RESUMEN GENERAL
A2: MUNICIPIO | B2: APORTACIÓN | C2: RECUPERADO | D2: PENDIENTE DE RECUPERAR | E2: AVANCE RECUPERACIÓN DE LA INVERSIÓN | F2: UTILIDAD ESPERADA | G2: UTILIDAD COBRADA | H2: AVANCE DE COBRO DE UTILIDAD | I2: ACCIONES
A3: BALANCÁN | B3: =BALANCAN!E4 -> 1000000 | C3: =BALANCAN!G4 -> 289151.78 | D3: =GENERAL!$B3-GENERAL!$C3 -> 710848.22 | E3: =IF(Table_1[[#This Row],[RECUPERADO]]/Table_1[[#This Row],[APORTACIÓN]]>=100%,100%,Table_1[[#This Row],[RECUPERADO]]/Table_1[[#This Row],[APORTACIÓN]]) -> 0.28915178 | F3: =COMALCALCO!I2 -> 0 | G3: 0 | H3: SIN UTI | I3: YA SE NOS ASIGNO LA PRIMERA OBRA PARA EL 2026, SIN EMBARGO SE REQUIERE OBTENER PROYECTOS POR MÍNIMO $5MDP CON UTILIDAD DEL 25% PARA PODER RECUPERAR LA INVERSIÓN Y TENER UTILIDAD DE $1MDP.
A4: CENTLA | B4: =CENTLA!E4 -> 3000000 | C4: =CENTLA!G4 -> 2942133.1 | D4: =GENERAL!$B4-GENERAL!$C4 -> 57866.904 | E4: =IF(Table_1[[#This Row],[RECUPERADO]]/Table_1[[#This Row],[APORTACIÓN]]>=100%,100%,Table_1[[#This Row],[RECUPERADO]]/Table_1[[#This Row],[APORTACIÓN]]) -> 0.98071103 | F4: =CENTLA!I4 -> -3000000 | G4: 0 | H4: =Table_1[[#This Row],[UTILIDAD COBRADA]]/Table_1[[#This Row],[UTILIDAD ESPERADA]] -> 0 | I4: YA SE ASIGNO LA PRIMERA OBRA DEL 2026, CON LA CUAL SE RECUPERA EL 100 DE LA INVERSIÓN Y SE TENDRA UNA UTILIDAD DE APROX $778,740 PESOS. NOS DARÁN MAS OBRAS PARA ESTE 2026
